print('before exception')
raise ValueError('supplied value is incorrect')
print('after exception')
